Workbook

Sheet Dashboard
A1: SPRAYCATION OUTREACH DASHBOARD
A2: 2025 Recap | 2026 Pipeline | Brand Targets
A4: 2025 OUTREACH SUMMARY
A5: Total Outreach Contacts | B5: =COUNTA('2025 Outreach'!B2:B500) -> 334
A6: No Response | B6: =COUNTIF('2025 Outreach'!J2:J500,"No response") -> 76
A7: Declined | B7: =COUNTIF('2025 Outreach'!J2:J500,"Declined") -> 11
A8: In Conversation | B8: =COUNTIF('2025 Outreach'!J2:J500,"In conversation") -> 2
A9: Confirmed Sponsors | B9: =COUNTIF('2025 Outreach'!J2:J500,"Confirmed Sponsor") -> 2
A10: 2026 High Potentials | B10: =COUNTIF('2025 Outreach'!J2:J500,"2026 High Potential") -> 10
A11: Closed Conversations | B11: =COUNTIF('2025 Outreach'!J:J,"*Closed*") -> 4
A12: Not Yet Contacted | B12: =COUNTIF('2025 Outreach'!J2:J500,"Not contacted") -> 41
A14: OUTREACH BY CITY (2025)
A15: City | B15: Count
A16: Portland | B16: =COUNTIF('2025 Outreach'!A2:A500,"Portland") -> 71
A17: Seattle | B17: =COUNTIF('2025 Outreach'!A2:A500,"Seattle") -> 55
A18: National | B18: =COUNTIF('2025 Outreach'!A2:A500,"National") -> 52
A19: Denver | B19: =COUNTIF('2025 Outreach'!A2:A500,"Denver") -> 49
A20: Vancouver | B20: =COUNTIF('2025 Outreach'!A2:A500,"Vancouver") -> 38
A21: Bozeman | B21: =COUNTIF('2025 Outreach'!A2:A500,"Bozeman") -> 30
A22: Boise | B22: =COUNTIF('2025 Outreach'!A2:A500,"Boise") -> 28
A23: Taos | B23: =COUNTIF('2025 Outreach'!A2:A500,"Taos") -> 8
A24: Jackson Hole | B24: =COUNTIF('2025 Outreach'!A2:A500,"Jackson Hole") -> 4
A26: 2026 BRAND TARGETS PIPELINE
A27: Total Brand Targets | B27: =COUNTA('2026 Brand Targets'!C2:C28) -> 27
A28: Magic Maker ($25K) | B28: =COUNTIF('2026 Brand Targets'!A2:A28,"*Magic Maker*") -> 8
A29: Culture Partner ($15K) | B29: =COUNTIF('2026 Brand Targets'!A2:A28,"*Culture Partner*") -> 8
A30: Community Ally ($5K) | B30: =COUNTIF('2026 Brand Targets'!A2:A28,"*Community Ally*") -> 11
A31: HIGH Priority | B31: =COUNTIF('2026 Brand Targets'!H2:H28,"HIGH") -> 14
A32: MEDIUM Priority | B32: =COUNTIF('2026 Brand Targets'!H2:H28,"MEDIUM") -> 12

Sheet 2026 Brand Targets
A1: Tier | B1: Category | C1: Brand / Company | D1: Website | E1: Why This Brand? | F1: Contact Strategy | G1: Estimated IG Followers | H1: Priority | I1: Status | J1: Notes
A2: Magic Maker ($25K) | B2: Art & Creative Brands | C2: Montana Cans (MTN Colors) | D2: montanacolors.com | E2: Leading spray paint brand globally — direct product alignment with mural creation. Potential for in-kind + cash sponsorship. | F2: Direct outreach to US distributor / marketing team | G2: 150K+ | H2: HIGH | J2: Could supply paint + sponsor. Perfect product fit.
A3: Magic Maker ($25K) | B3: Art & Creative Brands | C3: Liquitex (Colart Group) | D3: liquitex.com | E3: Professional-grade acrylic brand used by muralists worldwide. Portfolio includes spray paint line. | F3: Contact brand partnerships / artist relations | G3: 200K+ | H3: HIGH | J3: Artist sponsorship program exists. Strong alignment.
A4: Magic Maker ($25K) | B4: Art & Creative Brands | C4: Blick Art Materials | D4: dickblick.com | E4: Largest art supply retailer in the US. Deep roots in creative communities. | F4: Corporate partnerships / community programs team | G4: 250K+ | H4: HIGH | J4: National footprint. Community-focused brand.
A5: Magic Maker ($25K) | B5: Outdoor & Adventure | C5: REI Co-op | D5: rei.com | E5: Values-driven outdoor brand with deep community engagement. Co-op model aligns with Spraycation's community ethos. | F5: REI Cooperative Action Fund / brand partnerships | G5: 2M+ | H5: HIGH | J5: Strong CSR. 'Opt Outside' campaign alignment.
A6: Magic Maker ($25K) | B6: Outdoor & Adventure | C6: Subaru of America | D6: subaru.com | E6: Road trip brand. National parks partnerships. Strong values alignment with adventure + community. | F6: Corporate sponsorship / brand experience team | G6: 1M+ | H6: HIGH | J6: Love Promise initiative. Vehicle sponsorship potential.
A7: Magic Maker ($25K) | B7: Outdoor & Adventure | C7: Patagonia | D7: patagonia.com | E7: Mission-driven brand supporting grassroots environmental and social causes. Art as activism aligns. | F7: Environmental grants / brand partnerships | G7: 5M+ | H7: MEDIUM | J7: Highly selective. Worth pursuing for alignment.
A8: Magic Maker ($25K) | B8: Women-Led & Empowerment | C8: Bumble | D8: bumble.com | E8: Women-first platform. All-female creative team resonates. Community activation synergy. | F8: Brand marketing / community partnerships | G8: 3M+ | H8: HIGH | J8: Fund for women-led initiatives. Great fit.
A9: Magic Maker ($25K) | B9: Women-Led & Empowerment | C9: Aerie (American Eagle) | D9: ae.com/aerie | E9: Body positivity, empowerment messaging, community-driven. #AerieREAL campaign overlap. | F9: Brand partnerships / community marketing | G9: 1.5M+ | H9: MEDIUM | J9: Real campaign aligns with 'You Are Magic' message.
A10: Culture Partner ($15K) | B10: Lifestyle & Wellness | C10: Hydro Flask | D10: hydroflask.com | E10: Outdoor lifestyle brand based in Bend, OR. Pacific NW roots match tour geography. | F10: Brand partnerships / outdoor marketing | G10: 500K+ | H10: HIGH | J10: Parks for All philanthropy. In-kind + cash potential.
A11: Culture Partner ($15K) | B11: Lifestyle & Wellness | C11: Olipop | D11: drinkolipop.com | E11: Trendy prebiotic soda. Young, creative audience. Perfect for mural reveal events. | F11: Brand partnerships / event sponsorship | G11: 500K+ | H11: HIGH | J11: Event activation natural fit. In-kind + cash.
A12: Culture Partner ($15K) | B12: Lifestyle & Wellness | C12: Athletic Brewing Co. | D12: athleticbrewing.com | E12: Non-alcoholic craft beer. Community-focused, fits event activations perfectly. | F12: Marketing / event partnerships | G12: 200K+ | H12: HIGH | J12: NA beer = inclusive events. Growing brand.
A13: Culture Partner ($15K) | B13: Lifestyle & Wellness | C13: Poppi | D13: drinkpoppi.com | E13: Prebiotic soda brand with vibrant visual identity. Colorful brand matches Spraycation aesthetic. | F13: Marketing / influencer partnerships | G13: 400K+ | H13: MEDIUM | J13: Colorful brand. Event sampling synergy.
... A28: Community Ally ($5K) | B28: Travel & Hospitality | C28: Hipcamp | D28: hipcamp.com | E28: Outdoor stays platform. Adventure + road trip audience. Nature-meets-culture. | F28: Brand partnerships / creator program | G28: 200K+ | H28: LOW | J28: Road trip narrative. Content partnership angle.

Sheet 2025 Outreach
A1: City | B1: Company Name & website | C1: Why? | D1: Contact info | E1: Date | F1: Method of contact | G1: Notes: | H1: IG handle | I1: IG followers | J1: Status
A2: Boise | B2: Gleam Esthetika & Gallery Om Boise (health and wellness with gallery attached) https://www.gleamesthetika.com/ | C2: in kind, or sponsorship. This place is female owned, operated and is in opening the gallery this year | D2: Tahirah@gleamesthetika.com | E2: 45813 | F2: Direct email | G2: She is VERY interested in helping us out. Maybe a gallery talk at Gallery Om. Her space doesn't have a wall for a mural itself. She is working to conenct us with others in the Boise community incl Totally Boise, (local print magazine.) | H2: @gleam_esthetika | I2: 250 followers | J2: 2026 High Potential
A3: Boise | B3: Wild Ginger Makers Space https://www.wildgingermakersspace.com/ | C3: I recently opened a community studio space with another local artist and am ridiculously excited about what we have created! BOLT Handmakers Society is a place where folks can come to learn, teach, make, and gather. We host craft nights, sewing and textile art classes, gallery shows and more! | D3: WILDGINGERBOISE@GMAIL.COM | H3: none
A4: Boise | B4: Sagebrush Collective https://www.sagebrushcollaborative.com/ | C4: Inclusive art market. Confluence Market Interested in joining us for one of our community orientated monthly night markets? | D4: Jess Wagner, founder and sole owner of Sagebrush, is a 29-year-old fine artist based in Boise, Idaho. Passionate about artist collectives and vendor shows, she also runs Jess Wagner Art/Equinox Fox Goods, specializing in printmaking on secondhand clothing and repurposing outdoor gear. sagebrushcollab@gmail.com | H4: @sagebrushcollaborative | I4: 10.1k followers
A5: Boise | B5: Boise Art Revel https://www.boiseartrevel.com/ | C5: Slated to open by end of June 2025, this art gallery/community venue promises a multi-dimensional experience: rotating exhibitions, immersive digital installations, a working artist’s studio (Joelle Ater), craft-cocktail lounge, workshops, an art book library, AI + design competitions, and open-access art supplies for creativity. A “new hub to hang, make, sip, and dream big.” | D5: Joelle@BoiseArtRevel.com
A6: Boise | B6: Treasure Valley Children's Theater https://www.treasurevalleychildrenstheater.com/ | C6: theater for kids / art programs. aligns with our message | D6: info@treasurevalleychildrenstheater.com | E6: 45813 | F6: Direct email | G6: Looking for after school or youth programs to work with | H6: @tvchildrenstheater | I6: <1,500 followers | J6: No response
A7: Boise | B7: Salt Sanctuary (health and wellness) https://www.salt-sanctuary.com/ | C7: in kind, day of relaxation | D7: instagram DM info@salt-sanctuary.com | E7: 45813 | F7: Instagram | H7: @boisesaltsanctuary | I7: 4k followers | J7: No response
A8: Boise | B8: Encore Creative Center https://www.encorecreativecenter.com/ | C8: sponsor / networking | D8: learn@encorecreativecenter.com | E8: 45813 | F8: Direct email | G8: 2 locations in ID | H8: @encorecreativecenter | I8: 1500 followers | J8: No response
A9: Boise | B9: The Sparrow hotel https://sparrowboise.com/ | C9: in kind, lodging; sponsor. Downtown boutique hotel | D9: info@sparrowBoise.com | E9: 45813 | F9: Mulitple | G9: modern / hip lookings | H9: @sparrowboise | I9: 1400 followers | J9: No response
A10: Boise | B10: Dope Boxing (photos are all of female atheletes.) | C10: all female atheletes | D10: IG only | E10: 45813 | F10: Instagram | G10: not able to find links now, out of business?
A11: Boise | B11: Caffeina Coffee in Boise https://caffeinacoffee.com/ | C11: in kind, beverage or sponsorship | D11: info@caffeinacoffee.com | E11: 45813 | F11: Direct email | H11: @caffeinaroastingco | I11: 4,400 followers | J11: No response
A12: Boise | B12: Cycle Bar in Idaho,franchise https://www.cyclebar.com/location/village-meridian | C12: female led business, female atheletes | D12: villiagemeridian@cyclebar.com | E12: 45813 | F12: Direct email | G12: franchise so maybe there are too many restrictions | H12: @cyclebar this is the one branded IG page vs location specific | I12: 63.1 followers | J12: No response
A13: Boise | B13: Asana Climbing Gym, great mission station. Local Boise business | C13: great mission statement: to facilitate a positive environment and atmosphere, full of challenges and excitement, in order to create personal and community growth | D13: inquiry@asanaclimbing.com | E13: 45813 | F13: Direct email | J13: No response
A14: Boise | B14: Mystery Ranch retail | D14: website and Instagram; nothing for marketing or sales per se; sponsorships are 'donations' and that doesn't fit | E14: 45833 | F14: Instagram
A15: Boise | B15: Northface | D15: Instagram - website sucks portal is only for sales support | E15: 45840 | F15: Instagram
A16: Boise | B16: Push Pour Coffee (3 locations) https://www.pushandpour.com/pages/garden-city | C16: Push and Pour is more than just a coffee shop—it's a hub for creativity, community, and friendship, deeply rooted in Boise's skateboarding culture. the Garden City location has a great wall! and close to Rosa (see below) it looks like. | D16: info@pushandpour.com | H16: @pushandpour | I16: 15.9k Followers
A17: Boise | B17: Rosa Garden City restaruant https://www.rosagardencity.com/ | C17: comes up as one of the hottest places in Boise, Mexican taco shack, great wall possiblity | D17: Listening@rosagardencity.com concept is by a larger restaurant group, see next line | H17: cannot find it
A18: Boise | B18: Wylder Hospitality Group https://www.wylderhospitalitygroup.com/ | C18: have multiple concepts in Boise | D18: cannot find a central email or IG account | H18: cannot find it
A19: Boise | B19: Rose Entertainment Group https://www.roseentertainmentpnw.com/ | C19: in Portland and Seattle as well as Boise. Event / rave productions | H19: @roseentertainmentBoise | I19: only 2,400
A20: Boise | B20: Boise Creative Center https://boise-creative.com/ | C20: from an article: Alex grew up in Nampa and worked in finance before quitting his day job to pursue art full-time. He specializes in murals and his work can be seen at many local businesses, including Western Collective, Split Rail Winery, PreFunk Beer Bar, Prestige Water Sports, Boise Juice Company, North End Organic Nursery, and many more! He is known for his upbeat attitude and goofball personality and has created an unforgettable atmosphere at Boise Creative Center. Located at 1204 W Front St., Vega has transformed the old A1 building into a fun, relaxed space to bring out the creative energy in everyone. Boise Creative Center is an art commission studio and gallery warehouse, as well as an event center for art classes and parties. Spend a night out at the popular Friday night Paint n’ Sip class for adults and create a masterpiece, or bring your children in every second Sunday of the month to the Kids Paint Party. Private parties can be booked for any occasion. In addition to public and private painting classes, Boise Creative Center offers custom canvas paintings, murals, commercial signs, illustration, graphic design and printing, web design, commercial and residential painting.
A21: Boise | B21: Freak Alley Gallery https://www.freakalleyboise.com/ | C21: Located between 8th and 9th street and Bannock and Idaho in downtown Boise, Freak Alley is currently recognized as the largest open-air mural gallery in the northwestern United States. | D21: freakalley@baumrevision.com New works are formally added on a nearly annual basis, usually an event during the summer, either painting over or being incorporated into older murals or covering vacant space. The project is supported solely by volunteer work and donations in the form of money and art supplies. | H21: @freakalleygallery | I21: 4k followers
A22: Boise | B22: Poetic Tiger Gallery https://poetictiger.com/about/ | C22: Boise contempary art gallery; The gallery nurtures creative communities through presentations, workshops, mentorships, commissions, and educational events that deepen the conversation around contemporary art. Each year, partnerships with artists and organizations support fundraisers that strengthen community impact. | D22: hello@poetictiger.com | H22: @poetictigergallery | I22: 12.5k followers
A23: Boise | B23: HyperLUX Mag https://hyperluxmagazine.com/category/art/ | C23: Interview or feature or collab with this art magazine produced by Boise art gallery Poetic Tiger | D23: partners@hyperluxmagazine.com | H23: @hyperluxmagazine | I23: 13.5k followers
A24: Boise | B24: Visit Boise visitboise.com | C24: local and national - thanks to their supportive partnerships, they are able to get visiting media connections and help connect you with local reporters, story ideas and pitch development | D24: John Curtis, john.curtis@fahlgren.com
A25: Boise | B25: Idaho Statesman | C25: Boise's primary newspaper; one of two daily newspapers that operate out of Boise
A26: Boise | B26: City Lifestyle Magazine Boisecitylifestyle.com | C26: Print and digital magazine for local living | D26: Editorial: Vince.Gewalt@LifestylePubs.com | H26: @boiselifestyle | I26: 6k followers
A27: Boise | B27: Boise Weekly. Idaho Press Idahopress.com | H27: @boiseweekly | I27: 33k followers
A28: Boise | B28: Totally Boise TotallyBoise.com | C28: Tahira has been featured. Hoping for a warm intro. This is local & travel website, focusing on culture, food, events, business and people | H28: @totallyboise | I28: 60.9k followers
A29: Boise | B29: Boise Art Museum | C29: emailed on July 24th | D29: Amber@boiseartmuseum.org
A30: Bozeman | B30: Bozeman Hot Springs https://bozemanhotsprings.co/ | C30: in kind, day of relaxation | D30: info@bhsprings.com | E30: 45813 | F30: Mulitple | H30: @bozemanhotsprings | I30: 11.8k followers | J30: No response
A31: Bozeman | B31: The Clean Slate Group https://www.cleanslategroup.org/ | C31: , City of Bozeman, and Gallatin Art Crossing have come together to facilitate the A.R.T. Project, or “Artistically Reclaimed Trafficbox.” | D31: website portal, no specific email on the site | E31: 45813 | F31: Website portal | H31: @cleanslateroup | I31: <250 followers | J31: No response
A32: Bozeman | B32: Apres Brewing & Coffee in Bozeman https://drinkapresbeer.com/ | C32: locally owned, beer and NA brews | D32: cory@drinkapresbeer.com and Tyler@drinkspresbeer.com | F32: Mulitple | G32: in conversation, no funds but very generous with another lead | H32: @apresbeer | I32: 1500 followers | J32: Declined
A33: Bozeman | B33: Big Sky resort | C33: big employer in town | D33: megan.munley@bigskyresort.com plus website portal and Instagram | E33: 45824 | F33: Mulitple | H33: @bigskyresort | I33: 288k followers | J33: No response
A34: Bozeman | B34: Evrgreen Clothing Boutique https://www.evrgreenclothing.com/ | C34: on Main street | D34: Instagram | E34: 45824 | F34: Instagram | H34: @evrgreen_clothing | I34: 7,500 followers | J34: No response
A35: Bozeman | B35: Intrigue Ink https://intrigue.ink/ | C35: - two sisters started and run this small independant silk screening art clothing shop, made it regionally | D35: Instagram | E35: 45824 | F35: Instagram | H35: @intrigueink | I35: 14.1k followers | J35: No response
A36: Bozeman | B36: Gallantin Art Crossing, sculpture garden & public art gallery http://gallatinartcrossing.com/ | D36: portal and IG only | E36: 45824 | F36: Mulitple | H36: @gallantinartcrossing | I36: <500 followers | J36: No response
A37: Bozeman | B37: SLAM, non profit public art organization https://www.slamfestivals.org/ | C37: mural festival | D37: Noah via info@slamfetivals.org | E37: 45824 | F37: Direct email | G37: emailed us we were too late for any opportuities this year, try next year | H37: outdated. @slamfestivals | I37: 1800 followers | J37: 2026 High Potential
A38: Bozeman | B38: Snowflake AI | C38: Bozeman and Denver offices | D38: website portal, no IG account and no emails for media or marketing | E38: 45833 | F38: Website portal
A39: Bozeman | B39: Workiva Software | C39: headquarters in Bozeman | D39: website portal | E39: 45833 | F39: Website portal
A40: Bozeman | B40: Cannary District; the whole space | D40: https://www.cannerydistrict.com/contact; website portal | E40: 6/25th
...

Sheet Austin Only
A1: City | B1: Company Name & website | C1: Why? | D1: Contact info | E1: Date | F1: Method of contact | G1: Notes: | H1: IG handle | I1: IG followers | J1: Status
A2: Austin

Sheet Videographers
A1: City | B1: Company Name & website | C1: Why? | D1: Contact info | E1: Date | F1: Method of contact | G1: Notes: | H1: IG handle | J1: Status
A2: Boise | B2: Claire Keener | C2: Boise Photographer & Videographer | D2: kenner.photoco@gmail.com | H2: @kenner.photoco | I2: 187 followers | J2: 2026 High Potential
A3: Portland | B3: Eva Moss evamoss.com | C3: female solo business does a full workup of video production including smaller projects. Website shows work with Lulumon and a variety of both personal and commerical and social justice projects | D3: eva@evamoss.com | H3: @lezglam | I3: 1600 followers
A4: Portland | B4: Sara T (found in Upwork) | C4: 5 stars and very reasonal hourly rate. I’m experienced in all phases of video production, and I worked in fast-paced environments that required flexibility and creative problem-solving. My previous work included operating cameras, microphones, lighting as well as storyboarding, and post-production. I also do graphic design and motion graphics design. | D4: https://www.upwork.com/freelancers/~01154668a459da6b2b?mp_source=share
A5: Portland | B5: Garret B (found in Upwork) his company if Marmalade Creative https://garrettbennion.com/ | C5: 5 stars, good ratings/reviews My name is Garrett, I'm a driven Videographer, Video Director, and Cinematographer based in Portland, OR. I work on a range of projects with budgets small to large, but specialize in marketing videos, interview setups, event coverage, and brand story films. | D5: website portal | H5: @garrettbennion (personal mostly) his website is more professional | I5: 1300 followers
A6: Portland | B6: Lorddscreation, avier Damo https://lorddscreation.myportfolio.com/about | C6: Hello! My name is Xavier Damo. I'm a freelance photographer based in Portland, Oregon, specializing in live music and event photography. I'm known for capturing high- energy, candid moments that tell real stories. Whether its a concert, private event, or local gathering, I focus on preserving the atmosphere and emotion of every moment. Let's work together to create memories you'll never forget. | H6: @lorddscreation_media | I6: 1400 followers
A7: Portland | B7: Lost Fox Creative, Andrew Shepherd https://lorddscreation.myportfolio.com/about | C7: Lost Fox Creative In an effort to preserve brand stories and genuine sentiment, Lost Fox Creative brings a sense of reverence to projects it’s involved with, taking great care to capture a brand’s message, and impact its audience with authentic marketing | D7: lostfoxproductions@gmail.com | H7: @lostfoxcreative Vimeo: https://vimeo.com/lostfoxcreative | I7: 4k followers
A8: Portland | B8: allove Media, Isaiah Kerlegan | C8: Isaiah Kerlegan | Portland Videographer & Photographer; All Love | Everyone has a story | D8: no website | G8: @allovemedia | H8: 10k followers
A9: Portland | B9: MJ Romero Clark | Photo & Video Creator | Social Media Manager | C9: also a photograher and you see a lot of aerial work & gallery involvment | D9: mromero.clark@gmail.com | G9: @mj_pdx | H9: 10k followers
A10: Portland | B10: Matt | C10: Booked for Portland | F10: Instagram
A11: Seattle | B11: Mira Redko Seattle Photo & Video | D11: DM on IG | F11: Instagram | H11: @miraredkophotoandvideo | I11: 1,590 followers
A12: Portland | B12: Jacob & Megan Norwood, Photo and Video pacificnorwoods.com | D12: DM on IG | F12: Instagram | H12: @pacificnorwoods | I12: 169 followers
A13: Seattle | B13: Stevie Shao | D13: DM on IG | F13: Instagram | H13: @stepfrae | I13: 57.2k followers
A14: Seattle | B14: Seattle Video Photo | C14: Specializing in B2B video production, corp videos | D14: DM on IG | F14: Instagram | H14: @seattle_video_photo | I14: 29 followers
A15: Seattle | B15: Pixel & Pine | C15: super 8 + Storytelling | D15: DM on IG | F15: Instagram | H15: @pixelandpine | I15: 147 followers
A16: Seattle | B16: Growing Boy Media | D16: DM on IG | F16: Instagram | H16: @growingboymedia | I16: 1,325 followers
A17: Seattle | B17: Steven Luong | D17: DM on IG | F17: Instagram | H17: @steven.t.luong | I17: 37.6k followers
A18: Seattle | B18: Jonathan Furlong | D18: DM on IG | F18: Instagram | G18: send based in Seattle but really out of LA | H18: @jonathanfurlong | I18: 14.7k followers
A19: Vancouver | B19: Chase, Videographer | C19: Zuzu's friend, Incredible - top choice for content
A20: Vancouver | B20: Jeremy Au Yeung jeremyay.com | C20: portraits, documentary, street, lifestyle and weddings | F20: Instagram | H20: @ithejeremyay | I20: 1,485 followers
A21: Vancouver | B21: Carolyn Wong | C21: illustration, murals & Painting, tattoo | F21: Instagram | H21: @seeroro_ | I21: 12.6 k followers
A22: Denver | B22: Ave | C22: Founder of @thegroupchatdenver | F22: Instagram | H22: @avereem | I22: 5589 Followers
A23: Boise | B23: Kyle Moeller tgn-productions.com | C23: great price | D23: contact@tgn-productions.com 916-934-8098 | F23: Instagram | G23: booked for Boise | H23: @tgn_productions | I23: 33.2k | J23: Confirmed Sponsor
A24: Vancouver

Sheet 2025 Thank yous
A1: City | B1: Contact's Name | C1: Mailing address | D1: Shirt size | E1: Sticker Pack | F1: Postcard Pack | G1: Thank you letter
A2: Other city | B2: Dan B (+6 yr daughter) | C2: 1710 Puglia CT Rockwall, TX | E2: =TRUE() -> TRUE | F2: =TRUE() -> TRUE | G2: =TRUE() -> TRUE
A3: Other city | B3: Bianca & Scott | C3: 15613 Cabrillo Way 79738 Angel Fire, NM | D3: S | E3: =TRUE() -> TRUE | F3: =TRUE() -> TRUE | G3: =TRUE() -> TRUE
A5: Sante Fe | B5: Daddy Ernest Clark & Sons Truck | C5: 4300 Airport Rd Santa Fe, NM 87507 | D5: XL | E5: =TRUE() -> TRUE | F5: =TRUE() -> TRUE | G5: =TRUE() -> TRUE
B6: Erik Fink - Welding work on bumper and generator exhaust | C6: 2190 county road 105. Hutto tx. 78634 | E6: =TRUE() -> TRUE | F6: =TRUE() -> TRUE | G6: =TRUE() -> TRUE
A7: Taos | B7: Daddy Russel Payton - Mechanic Tao | C7: 827 Paseo del Pueblo sur Taos nm 87571 | E7: =TRUE() -> TRUE | F7: =TRUE() -> TRUE | G7: =TRUE() -> TRUE
B8: Bobby Zakes - Paint hook-up Greenling | C8: 34797 Pleasant Lane Evergreen, CO 80439 | E8: =TRUE() -> TRUE | F8: =TRUE() -> TRUE | G8: =TRUE() -> TRUE
B9: Marshall McKee | C9: 1135 s. Gray st. Lakewood, CO 80232 | D9: XL | E9: =TRUE() -> TRUE | F9: =TRUE() -> TRUE | G9: =TRUE() -> TRUE
A10: Other city | B10: Scott Keating w/ Nemo Design | C10: 20541 Gloucester LN Bend, OR 97701 | D10: L | E10: =TRUE() -> TRUE | F10: =TRUE() -> TRUE | G10: =TRUE() -> TRUE
A11: Bozeman | B11: Tyler Nail w/ Apres Brewing (already gave shirt) | C11: 1216 West Lincoln Street A, Bozeman, MT 59715 | D11: no shirt | E11: =FALSE() -> FALSE | F11: =FALSE() -> FALSE | G11: =FALSE() -> FALSE
B12: Patrick Schect | E12: =FALSE() -> FALSE | F12: =FALSE() -> FALSE | G12: =FALSE() -> FALSE
B13: FIVER Video Editor !??!?! | E13: =FALSE() -> FALSE | F13: =FALSE() -> FALSE | G13: =FALSE() -> FALSE
A14: Denver | B14: Town Hall Collective Hidden Gem | C14: 525 Santa Fe, Denver Colorado 80204 | D14: no shirt | E14: =TRUE() -> TRUE | F14: =TRUE() -> TRUE | G14: =TRUE() -> TRUE
A15: Denver | B15: Nam Nguyen Videographer / Editor | D15: M | E15: =TRUE() -> TRUE | F15: =TRUE() -> TRUE | G15: =TRUE() -> TRUE
A16: Other city | B16: May Museum of Natural History Mom & Daughter interview | C16: Colorado Springs, CO | D16: S | E16: =TRUE() -> TRUE | F16: =TRUE() -> TRUE | G16: =TRUE() -> TRUE
A17: Taos | B17: Johnson's Itty Bitty Farm | C17: 1430 Martin Ln. Boone, CO 81205 | D17: S | E17: =FALSE() -> FALSE | F17: =FALSE() -> FALSE | G17: =FALSE() -> FALSE
A18: Taos | B18: Luna Mystica stickers & postcards x 3 | D18: no shirt | E18: =FALSE() -> FALSE | F18: =FALSE() -> FALSE | G18: =FALSE() -> FALSE
A19: Taos | B19: Metamorphic Vintage stickers & postcards | C19: 218 B Paseo Del Pueblo Sur, Taos, NM 87571 | D19: L | E19: =FALSE() -> FALSE | F19: =FALSE() -> FALSE | G19: =FALSE() -> FALSE
A20: Boise | B20: Tahirah Razak @ Om Gallery | C20: 412 E 41st St Suite 5A Garden City, ID 83714 | E20: =FALSE() -> FALSE | F20: =FALSE() -> FALSE | G20: =FALSE() -> FALSE
A21: Denver | B21: Shaunie Berry & Tya Alisa Anthony | C21: Redline Comtemporary Arts Center 2350 Arapahoe St, Denver, CO 80205 | E21: =FALSE() -> FALSE | F21: =FALSE() -> FALSE | G21: =FALSE() -> FALSE
A22: Denver | B22: Ana Paula Pinto | Director of Programs & Operations | C22: DENVER'S ART DISTRICT ON SANTA FE 858 Sante Fe Drive, Denver CO 80204 | D22: M | E22: =TRUE() -> TRUE | F22: =TRUE() -> TRUE | G22: =TRUE() -> TRUE
A23: Portland | B23: Nossa Familia Coffee | E23: =FALSE() -> FALSE | F23: =FALSE() -> FALSE | G23: =FALSE() -> FALSE
A24: Portland | B24: DJ Aquamarine | E24: =FALSE() -> FALSE | F24: =FALSE() -> FALSE | G24: =FALSE() -> FALSE
A25: Portland | B25: Staff ? Mark & wife | C25: Crave Catering 1324 SE 8th Ave, Portland, OR | E25: =FALSE() -> FALSE | F25: =FALSE() -> FALSE | G25: =FALSE() -> FALSE
A26: Portland | B26: Logan, photographer | E26: =FALSE() -> FALSE | F26: =FALSE() -> FALSE | G26: =FALSE() -> FALSE
A27: Portland | B27: Matt, videographer | E27: =FALSE() -> FALSE | F27: =FALSE() -> FALSE | G27: =FALSE() -> FALSE
A28: Portland | B28: Emilia Quinton & staff Rebel Heart Therapy | C28: 11 NE Martin Luther King Jr Blvd Suite 203 Portland, OR 97232 | D28: no shirt | E28: =FALSE() -> FALSE | F28: =FALSE() -> FALSE | G28: =FALSE() -> FALSE
A29: Boise | B29: Kyle Moeller TNG Productions | E29: =FALSE() -> FALSE | F29: =FALSE() -> FALSE | G29: =FALSE() -> FALSE
A30: Portland | E30: =FALSE() -> FALSE | F30: =FALSE() -> FALSE | G30: =FALSE() -> FALSE
A31: Portland | E31: =FALSE() -> FALSE | F31: =FALSE() -> FALSE | G31: =FALSE() -> FALSE
A32: Portland | E32: =FALSE() -> FALSE | F32: =FALSE() -> FALSE | G32: =FALSE() -> FALSE
A33: Portland | E33: =FALSE() -> FALSE | F33: =FALSE() -> FALSE | G33: =FALSE() -> FALSE
A34: Portland | E34: =FALSE() -> FALSE | F34: =FALSE() -> FALSE | G34: =FALSE() -> FALSE
A35: Portland | E35: =FALSE() -> FALSE | F35: =FALSE() -> FALSE | G35: =FALSE() -> FALSE

Sheet 2026 High Potentials
A1: City | B1: Company Name & website | C1: Why? | D1: Contact name | E1: Email | F1: Notes: | G1: IG handle | H1: IG followers
A2: Bozeman | B2: SLAM, non profit public art organization https://www.slamfestivals.org/ | C2: mural festival - not sponsorship but great for interaction and exposure | D2: Noah | E2: info@slamfetivals.org | F2: Lead time - there is an application process to contribute and / or be involved in any way
A3: Denver | B3: 40 West Arts District | C3: arts | D3: Liz Black | E3: liz@40westarts.com | G3: @40westarts | H3: 6,600 followers
A4: Denver | B4: MiHi Entertainment | C4: photo booth activity for marketing / events | D4: Joyce Reilly | E4: <joyce@mihientertainment.com> | F4: she was willing to come out to reveal event to support and offer service for those attending
A5: Denver | B5: Zeppelin Station https://www.zeppelinstation.com/ | C5: (hosts murals and immersive installations) | D5: Joshua Schmitz | E5: staysocial@handsomeboys.com | F5: was totally interested but construction was still going on in 2025
A6: Denver | B6: Denver Arts District website and collective https://denversartdistrict.org/ | C6: This is the 'organizational' part of the arts district. They handle the big events there and serve as a summary and resource to all the businesses in the district | D6: Ana Paula Pinto | Director of Programs & Operations | E6: hello@denverartdistrict.org and anapaula@denverartdistrict.org | F6: Definitely helpful and wanted to take Zuzu around to introduce her to all the business owners and peeps active there
A7: Denver | B7: Street Wise Arts | C7: Our mission is to create mural projects, community events and youth education programs; in Boulder in their NoBo Arts district. They do a mural festival in September | D7: website portal: https://streetwisearts.org/ | F7: we were too late for this year's mural fest, look out for applications accepted for 2026 | G7: @streetwisearts | H7: 6,800 followers
A8: Denver | B8: 303 Magazine | C8: Mural Event coverage | D8: emailed Advertising which bounced back so submitted via portal & IG | F8: They responded to IG DMs and did an interview with Zuzu at the Denver reveal | G8: @303magazine | H8: 128k followers
A9: Denver | B9: The Pink Pearl - perm jewelery https://www.thepinkpearldenver.com/ | C9: We are committed to supporting our community by employing local welders and artisans, and facilitating pop-up events throughout the Front Range | D9: Annie Marshall, Owner thepinkpearlLTD@gmail.com | E9: reached out to Zuzu via IG | F9: She is trying to get a grant for $5k plus will put in $1,500 of her own money | G9: @pinkpearldenver | H9: 1,900 followers
A10: Portland | B10: Urbanite Portland https://www.urbanitepdx.com/ | C10: multi use space, film, gallery, market, events; Known to partner on creative and community-driven initiatives | E10: Instagram DM - all conversations were via IG, never gave me an email. | F10: in talks - no money but offered to host any event there free | G10: @urbanitepdx | H10: 49.2k followers
A11: Taos | B11: Luna Mystica https://hotellunamystica.com/ | C11: in kind, lodging. Great RV & retro trailer camping and event venue | D11: website portal or this email: reservations@hotelluna­mystica.com
A12: Portland | B12: Soaring Coffee | C12: Mobile event coffee catering - IG account only Looks small maybe more affordable, we can see if they do public sales and or get her interested in showing off at this market for her own marketing! Does OR and WA areas btw | E12: soaringcoffeeco@gmail.com | F12: Zuzu spoke to them in 2025 | G12: @soaringcoffee
A13: Portland | B13: Portal 503 | C13: big walls
A14: Salt Lake City | B14: SLUG MAG Fice Gallery And Boutique www.ficegallery.com | C14: loal photography magazine, gallery with rotating pop up shows, have a dope graff alley | D14: Grace Lund; owner Zuzu spoke with Emerson in the shop | E14: info@ficegallery.com | F14: Zuzu got contact in Nov 2025 | G14: @ficegallery | H14: 30.5k
A15: Salt Lake City | B15: Jetpackjohnson.com | C15: local muralist | G15: @jetpackjohnson_ | H15: 2338
A16: Salt Lake City | B16: coleeisenhour.com | C16: local muralist | G16: @_roadfish_ | H16: 2441
A17: Boise | B17: Patrick Fitz | G17: @patrickfitz77 | H17: 11.4k
A18: Boise | B18: Plunj 7088 W State Street boise.plunj.co | C18: Boise' premier location for hot sauna and cold plunge | G18: @plunj_boise | H18: 3366
A19: Boise | B19: Visit Idaho | C19: offical IG for the state | G19: @visitidaho | H19: 131k
A20: Boise | B20: IG Boise Insiders | C20: Boise food, culture and experiences | G20: @boiseinsiders | H20: 25.1k
A21: Boise | B21: Totally Boise newletter/mag totallyboise.com | C21: Culture Food Events People and Business. print and digital formats | G21: @totallyboise | H21: 60.9k
A22: Boise | B22: IG From Boise, things to do in Boise | C22: newletter and collabs | G22: @from.boise | H22: 31.2k
A23: Boise | B23: IG Cam Filmz | C23: photography and videography film, marketing and travel | E23: camfilmz1@gmail.com | G23: @cam.filmz | H23: 15.1k
A24: Boise | B24: IG Katilyn "wellness Girlies | C24: wellness, food, community events, travel, fashion etc | E24: dearboise@gmail.com | G24: @dear.boise | H24: 18.2k
A25: Boise | B25: Free Spirits Bev Co https://www.freespiritsbevco.com/ 518 N Curtis Rd, Boise, ID 83706 | C25: NA spirits in Boise; bottle shop as well as a wholesaler
A26: Boise | B26: This is Boise | C26: best of Boise and Treasure Valley. Thankgs to do places to be and where to stay | F26: costs money | G26: @thisisboise | H26: 115k
